Workbook

Sheet Brightline DCF Valuation
B3: x | C3: Revenue Forecast Model
C5: Periods | E5: 2023 | F5: 2024 | G5: 2025 | H5: 2026 | I5: 2027 | J5: 2028 | K5: 2029 | L5: 2030
C7: Ridership
C8: Short-Distance | E8: 1747762 | F8: 1135505 | G8: 1227198 | H8: =G8*(1+H34) -> 1448093.6 | I8: =H8*(1+I34) -> 1650826.7 | J8: =I8*(1+J34) -> 1824163.6 | K8: =J8*(1+K34) -> 1878888.5 | L8: =K8*(1+L34) -> 1935255.1
C9: Long-Distance | E9: 306131 | F9: 1628007 | G9: 1889125 | H9: =G9*(1+H35) -> 2078037.5 | I9: =H9*(1+I35) -> 2213109.9 | J9: =I9*(1+J35) -> 2301634.3 | K9: =J9*(1+K35) -> 2370683.4 | L9: =K9*(1+L35) -> 2441803.9
C10: Total | E10: =SUM(E9,E8) -> 2053893 | F10: =SUM(F9,F8) -> 2763512 | G10: =SUM(G9,G8) -> 3116323 | H10: =SUM(H8:H9) -> 3526131.1 | I10: =SUM(I8:I9) -> 3863936.7 | J10: =SUM(J8:J9) -> 4125797.9 | K10: =SUM(K8:K9) -> 4249571.8 | L10: =SUM(L8:L9) -> 4377059
C12: Average Fare per Passenger
C13: Short-Distance | E13: 22.31 | F13: 29.34 | G13: 26.1 | H13: =G13*(1+H38) -> 27.144 | I13: =H13*(1+I38) -> 27.95832 | J13: =I13*(1+J38) -> 28.517486 | K13: =J13*(1+K38) -> 28.802661 | L13: =K13*(1+L38) -> 29.090688
C14: Long-Distance | E14: 85.34 | F14: 73.2 | G14: 74.74 | H14: =G14*(1+H39) -> 76.2348 | I14: =H14*(1+I39) -> 77.759496 | J14: =I14*(1+J39) -> 78.537091 | K14: =J14*(1+K39) -> 79.715147 | L14: =K14*(1+L39) -> 80.910875
C16: Ticket Revenue
C17: Short-Distance | E17: =(E8*E13)/1000 -> 38992.57 | F17: =(F8*F13)/1000 -> 33315.717 | G17: =(G8*G13)/1000 -> 32029.868 | H17: =(H8*H13)/1000 -> 39307.054 | I17: =(I8*I13)/1000 -> 46154.343 | J17: =(J8*J13)/1000 -> 52020.559 | K17: =(K8*K13)/1000 -> 54116.988 | L17: =(L8*L13)/1000 -> 56297.903
C18: Long-Distance | E18: =(E9*E14)/1000 -> 26125.22 | F18: =(F9*F14)/1000 -> 119170.11 | G18: =(G9*G14)/1000 -> 141193.2 | H18: =(H9*H14)/1000 -> 158418.77 | I18: =(I9*I14)/1000 -> 172090.31 | J18: =(J9*J14)/1000 -> 180763.67 | K18: =(K9*K14)/1000 -> 188979.37 | L18: =(L9*L14)/1000 -> 197568.49
C19: Total | E19: =SUM(E17:E18) -> 65117.79 | F19: =SUM(F17:F18) -> 152485.83 | G19: =SUM(G17:G18) -> 173223.07 | H19: =SUM(H17:H18) -> 197725.83 | I19: =SUM(I17:I18) -> 218244.66 | J19: =SUM(J17:J18) -> 232784.22 | K19: =SUM(K17:K18) -> 243096.36 | L19: =SUM(L17:L18) -> 253866.39
C21: Passenger Food and Beverage | E21: 5917 | F21: 12495 | G21: 15003 | H21: =G21*(1+H41) -> 18003.6 | I21: =H21*(1+I41) -> 20704.14 | J21: =I21*(1+J41) -> 22774.554 | K21: =J21*(1+K41) -> 23913.282 | L21: =K21*(1+L41) -> 24630.68
C22: Passenger Ancillary | E22: 5306 | F22: 7892 | G22: 10504 | H22: =G22*(1+H42) -> 12604.8 | I22: =H22*(1+I42) -> 14495.52 | J22: =I22*(1+J42) -> 15945.072 | K22: =J22*(1+K42) -> 16742.326 | L22: =K22*(1+L42) -> 17244.595
C23: Affiliate Revenue | E23: 6920 | F23: 6977 | G23: 6977 | H23: 6977 | I23: 6977 | J23: 6977 | K23: 6977 | L23: 6977
C24: Advertising | E24: 2608 | F24: 5583 | G24: 5807 | H24: 5807 | I24: 5807 | J24: 5807 | K24: 5807 | L24: 5807
C25: Grants | E25: 1650 | F25: 2051 | G25: 2029 | H25: 2029 | I25: 2029 | J25: 2029 | K25: 2029 | L25: 2029
C26: Other Service Income | E26: 144 | F26: 457 | G26: 491 | H26: 491 | I26: 491 | J26: 491 | K26: 491 | L26: 491
C27: Total Ancillary Revenue | E27: =SUM(E21:E26) -> 22545 | F27: =SUM(F21:F26) -> 35455 | G27: =SUM(G21:G26) -> 40811 | H27: =SUM(H21:H26) -> 45912.4 | I27: =SUM(I21:I26) -> 50503.66 | J27: =SUM(J21:J26) -> 54023.626 | K27: =SUM(K21:K26) -> 55959.607 | L27: =SUM(L21:L26) -> 57179.276
C29: Total Revenue | E29: =SUM(E27,E19) -> 87662.79 | F29: =SUM(F27,F19) -> 187940.83 | G29: =SUM(G27,G19) -> 214034.07 | H29: =SUM(H27,H19) -> 243638.23 | I29: =SUM(I27,I19) -> 268748.32 | J29: =SUM(J27,J19) -> 286807.85 | K29: =SUM(K27,K19) -> 299055.97 | L29: =SUM(L27,L19) -> 311045.66
B31: x | C31: Growth Assumptions | E31: 2023 | F31: 2024 | G31: 2025 | H31: 2026 | I31: 2027 | J31: 2028 | K31: 2029 | L31: 2030
C33: Ridership
C34: Short-Distance | F34: =(F8-E8)/E8 -> -0.35030914 | G34: =(G8-F8)/F8 -> 0.080750855 | H34: =IF($E$44="Base Case",H49,IF($E$44="Best Case",H62,H75)) -> 0.18 | I34: =IF($E$44="Base Case",I49,IF($E$44="Best Case",I62,I75)) -> 0.14 | J34: =IF($E$44="Base Case",J49,IF($E$44="Best Case",J62,J75)) -> 0.105 | K34: =IF($E$44="Base Case",K49,IF($E$44="Best Case",K62,K75)) -> 0.03 | L34: =IF($E$44="Base Case",L49,IF($E$44="Best Case",L62,L75)) -> 0.03
C35: Long-Distance | F35: =(F9-E9)/E9 -> 4.3180077 | G35: =(G9-F9)/F9 -> 0.1603912 | H35: =IF($E$44="Base Case",H50,IF($E$44="Best Case",H63,H76)) -> 0.1 | I35: =IF($E$44="Base Case",I50,IF($E$44="Best Case",I63,I76)) -> 0.065 | J35: =IF($E$44="Base Case",J50,IF($E$44="Best Case",J63,J76)) -> 0.04 | K35: =IF($E$44="Base Case",K50,IF($E$44="Best Case",K63,K76)) -> 0.03 | L35: =IF($E$44="Base Case",L50,IF($E$44="Best Case",L63,L76)) -> 0.03
C37: Average Fare per Passenger
C38: Short-Distance | F38: =(F13-E13)/E13 -> 0.31510533 | G38: =(G13-F13)/F13 -> -0.11042945 | H38: =IF($E$44="Base Case",H53,IF($E$44="Best Case",H66,H79)) -> 0.04 | I38: =IF($E$44="Base Case",I53,IF($E$44="Best Case",I66,I79)) -> 0.03 | J38: =IF($E$44="Base Case",J53,IF($E$44="Best Case",J66,J79)) -> 0.02 | K38: =IF($E$44="Base Case",K53,IF($E$44="Best Case",K66,K79)) -> 0.01 | L38: =IF($E$44="Base Case",L53,IF($E$44="Best Case",L66,L79)) -> 0.01
C39: Long-Distance | F39: =(F14-E14)/E14 -> -0.14225451 | G39: =(G14-F14)/F14 -> 0.021038251 | H39: =IF($E$44="Base Case",H54,IF($E$44="Best Case",H67,H80)) -> 0.02 | I39: =IF($E$44="Base Case",I54,IF($E$44="Best Case",I67,I80)) -> 0.02 | J39: =IF($E$44="Base Case",J54,IF($E$44="Best Case",J67,J80)) -> 0.01 | K39: =IF($E$44="Base Case",K54,IF($E$44="Best Case",K67,K80)) -> 0.015 | L39: =IF($E$44="Base Case",L54,IF($E$44="Best Case",L67,L80)) -> 0.015
C41: Passenger Food and Beverage | F41: =(F21-E21)/E21 -> 1.111712 | G41: =(G21-F21)/F21 -> 0.20072029 | H41: =IF($E$44="Base Case",H56,IF($E$44="Best Case",H69,H82)) -> 0.2 | I41: =IF($E$44="Base Case",I56,IF($E$44="Best Case",I69,I82)) -> 0.15 | J41: =IF($E$44="Base Case",J56,IF($E$44="Best Case",J69,J82)) -> 0.1 | K41: =IF($E$44="Base Case",K56,IF($E$44="Best Case",K69,K82)) -> 0.05 | L41: =IF($E$44="Base Case",L56,IF($E$44="Best Case",L69,L82)) -> 0.03
C42: Passenger Ancillary | F42: =(F22-E22)/E22 -> 0.48737279 | G42: =(G22-F22)/F22 -> 0.33096807 | H42: =IF($E$44="Base Case",H57,IF($E$44="Best Case",H70,H83)) -> 0.2 | I42: =IF($E$44="Base Case",I57,IF($E$44="Best Case",I70,I83)) -> 0.15 | J42: =IF($E$44="Base Case",J57,IF($E$44="Best Case",J70,J83)) -> 0.1 | K42: =IF($E$44="Base Case",K57,IF($E$44="Best Case",K70,K83)) -> 0.05 | L42: =IF($E$44="Base Case",L57,IF($E$44="Best Case",L70,L83)) -> 0.03
B44: x | C44: Scenario | E44: Base Case
B46: x | C46: Base Case | E46: 2023 | F46: 2024 | G46: 2025 | H46: 2026 | I46: 2027 | J46: 2028 | K46: 2029 | L46: 2030
C48: Ridership
C49: Short-Distance | H49: 0.18 | I49: 0.14 | J49: 0.105 | K49: 0.03 | L49: 0.03
C50: Long-Distance | H50: 0.1 | I50: 0.065 | J50: 0.04 | K50: 0.03 | L50: 0.03
C52: Average Fare per Passenger
C53: Short-Distance | H53: 0.04 | I53: 0.03 | J53: 0.02 | K53: 0.01 | L53: 0.01
C54: Long-Distance | H54: 0.02 | I54: 0.02 | J54: 0.01 | K54: 0.015 | L54: 0.015
C56: Passenger Food and Beverage | H56: 0.2 | I56: 0.15 | J56: 0.1 | K56: 0.05 | L56: 0.03
C57: Passenger Ancillary | H57: 0.2 | I57: 0.15 | J57: 0.1 | K57: 0.05 | L57: 0.03
...
